Workbook
Name article1.body1.sec2.sec3.sec6.p1: Formulas!$C$49
Name article1.body1.sec2.sec3.sec6.p2: Formulas!$C$52
Name article1.body1.sec2.sec3.sec7.p1: Formulas!$C$59
Name article1.body1.sec2.sec3.sec7.p2: Formulas!$C$60
Name article1.body1.sec2.sec3.sec7.p3: Formulas!$C$61
Name article1.body1.sec2.sec3.sec7.p4: Formulas!$C$62
Name pcbi.1006343.e029: Formulas!$C$53

Sheet Hoja3
A1: Ideas
A2: Se puede usar la partición de maxima modularidad (MMP) para calcular la información integrada, pues se busca calcular II a través de la descomposcición más modular de una red neuronal
A3: a la luz de trabajos anteriores que han demostrado que la información fluye a través de módulos relativamente discretos en el cerebro
A4: We propose an alternative network partition acrosss which to calculate integrated information, whichis based on the graph-theoretic notion of modularity and bypasses the computational expense offinding the MIP and the artificiality of using the MIB.
A5: The modularity of a network quantifies theextent to which that network can be broken up into relatively discrete ”modules,” which are definedas densely interconnected communities of node
E7: Decomposing a neural network intoits ”Maximum Modularity Partition” (MMP) (Figure 1C) is therefore more congruent with what isknown about information flow in the brain than is calculating integrated information
E8: across the MIB,because it is reflects the underlying functional architecture of neural networks. The MMP has thefurther advantage over the MIP and the MIB in being extremely quick to find
A26: There are a number of ways of finding the MMP of a network. We utilized the Louvain Method fordetecting communities in graphs, which is a “greedy optimization” method and which seems to runon O(nlogn) time [25]
A28: Para encontrar la MMP, primero obtenemos una matriz de adyacencia a partir de datos de series temporales. Específicamente, tomamos la autocorrelación de la serie temporal y binarizamos la matriz de correlación resultante en un umbral dado [37].
A29: En este estudio, este umbral se fijó en una significancia estadística de alfa de 0,05 y en la mitad superior de la distribución de los valores absolutos de los coeficientes de correlación. Se cree que la matriz de adyacencia binaria resultante
A30: refleja la conectividad funcional de la red de la que se obtuvieron los datos de la serie temporal.
A31: The adjacency matrix is then fed into the Louvain Algorithm, which iterates through different net-work partitions to maximize network modularity Q:
A38: [25] Blondel VD, Guillaume JL, Lambiotte R, Lefebvre E. Fast unfolding of communities in largenetworks. Journal of statistical mechanics: theory and experiment. 2008;2008(10):P10008.
A39: (12) (PDF) Moving Past the Minimum Information Partition: How To Quickly and Accurately Calculate Integrated Information. Available from: https://www.researchgate.net/publication/301895994_Moving_Past_the_Minimum_Information_Partition_How_To_Quickly_and_Accurately_Calculate_Integrated_Information [accessed Mar 20 2024].
A44: Articulos con herramientas para analisis de redes
A45: [PDF] Exploring Network Structure, Dynamics, and Function using NetworkX | Semantic Scholar
A48: METODO DEL GRAFO DE FLUJO DE RED
A49: Se trata de encontrar la MIP de un sistema finito mediante la construcción de un grafo de flujo de red a partir de la tpm del sistema. El grafo se construye de tal manera que cada partición del sistema corresponde
A50: a una fuente y un destino en el grafo, y las aristas del grafo representan las transiciones entre estados. El algoritmo utiliza el flujo máximo en el grafo para encontrar la partición que maximiza la información integrada.
A51: Como sería el grafo?
B52: -Cada estado del sistema se representa como un nodo en el grafo.
B53: -Para cada par de estados presentes y futuros (i, j), donde i y j son estados del sistema, se crea una arista dirigida del estado presente (i) al estado futuro (j) con peso igual a la probabilidad de transición de i a j en la TPM.
A54: Como se asignarían los nodos fuente y destino?
A70: Calcular flujo máximo
B71: Se utiliza un algoritmo de flujo máximo, como el algoritmo de Ford-Fulkerson o el algoritmo de Edmonds-Karp, para calcular el flujo máximo en el grafo.
B72: El flujo máximo representa la cantidad máxima de información que puede fluir desde la fuente hasta el destino sin exceder las capacidades de las aristas.

Sheet Formulas
C1: Observaciones:
C2: En los ejemplos nosostros asumimos una estructura de la red como se ha mostrado en las figuras, pero en general no se conoce la estructura subyacente. La perturbación y la observación
C3: es lo que nos permite a quienes experimentamos, determinar la TPM
C5: Condiciones de background: Como el objetivo es evaluar la informacion integrada de un sistema candidatos cuando la red está en un estado en particular , entonces queremos determinar la TPM del sistema candidato
C6: perturbándolo mientras los elementos externos están fijos en ese estado. A esos elementos externos fijados se les conoce como condiciones de background para el sistema candidato
C11: Mecanismos condicionalmente independientes
C12: Matematicamente la independencia condicional se representa asi:
C16: lo que significa que dado el estado de un sistema en el tiempo t-1, la probabilidad de A, By C se puede calcular independientemente. Esto porque se supone que no hay interaccion instantanea entre
C17: los mecanismos y además que las CAUSAS deben preceder sus efectos. En nuestros modelos de sistemas físicos descartamos la causación instantánea, esto se captura por el requerimiento
C18: de que los elementos sean condicionalmente independientes. O sea que el estado de cada elemento en t+1 depende inicamente del estado del sistema en t y no de los estados de otros elementos en t+1
C20: Una vez que se escoge un conjunto candidato, según IIT, los elementos por fuera de ese conjunto son tratados como condiciones de background.
C21: Es decir, no se consideran como variables internas del conjunto sobre el que se hacen las perturbaciones, sino que se fijan sus valores y se tratan como condiciones externas.
... C30: Repertorio EFECTO
C31: El repertorio efecto | M31: se calcula fijando el estado actual de A en 1, mientras los elementos restantes B y C son independientemente
C32: perturbadas en todos sus posibles estados con igual probabilidad
C36: Otra vez, las entradas comunes de B o C pueden llevar a correlaciones entre | U36: y | V36: Se usan elementos virtualespara reemplazar los elementos B y C
C37: con salidas independientes a todos los elementos y asi evitar contar estas correlaciones como efectos de elementos.
C38: Como todos los mecanismos bajo consideración son condicionalmente independientes, en la práctica el repertorio efecto puede calcularse así:
C41: esto significa que el repertorio efecto de un solo elemento en el futuro, por ejemplo | V41: es simplemente:
C47: PyPHI: Toolbox for integration information
C48: Cause-effect structures (system-level information).
C49: The next step is to compute the CES, the set of all concepts specified by the subsystem. The CES characterizes all of the causal constraints that are intrinsic to a physical system. This is implemented by the pyphi.compute.ces() function, which simply calls Subsystem.concept() for every mechanism
C50: , where
C51: is the power set of subsystem nodes. It returns a CauseEffectStructure object containing those Concepts for which φ > 0.
C52: We see that every mechanism in
C53: except for AC specifies a concept, as described in Fig. 10 of [3]:
C58: Irreducible cause-effect structures (system-level integration).
C59: At this point, the irreducibility of the subsystem’s CES is evaluated by applying the integration postulate at the system level. As with integration at the mechanism level, the idea is to measure the difference made by each partition and then take the minimal value as the irreducibility of the subsystem.
C60: We begin by performing a system cut. Graphically, the subsystem is partitioned into two parts and the edges going from one part to the other are cut, rendering them causally ineffective. This is implemented as an operation on the TPM as follows: Let Ecut denote the set of directed edges in the subsystem that are to be cut, where each edge e ∈ Ecut has a source node a and a target node b. For each edge, we modify the individual TPM of node b (Fig 2) by marginalizing over the states of a at t. The resulting TPM specifies the function implemented by b with the causal influence of a removed. We then combine the modified node TPMs to recover the full TPM of the partitioned subsystem. Finally, we recalculate the CES of the subsystem with this modified TPM (the partitioned CES).
C61: The irreducibility of a CES with respect to a partition is the distance between the unpartitioned and partitioned CESs (calculated with pyphi.compute.ces_distance(); several distances are supported; see § Configuration). This distance is evaluated for every partition, and the minimum value across all partitions is the subsystem’s integrated information Φ, which measures the extent to which the CES specified by the subsystem is irreducible to the CES under the minimal partition.
C62: This procedure is implemented by the pyphi.compute.sia() function, which returns a SystemIrreducibilityAnalysis object (Fig 1). We can verify that the Φ value of the example system in [3] is 1.92 and the minimal partition is that which removes the causal connections from AB to C:

Sheet Ej1RepEfectSinEV
A1: Calculo Repertorio Efecto ejemplo
A3: Ahora vamos a calcular el repertorio efecto con elementos virtuales, ahora lo haremos sin elementos virtuales teniendo en cuenta lo xplicado en la hoja RepEfectoConEV
A4: tomando como referencia la siguiente formula:
A9: lo que significa que dado el estado de un sistema en el tiempo t-1, la probabilidad de A, By C se puede calcular independientemente. Esto porque se supone que no hay interaccion instantanea entre
A10: los mecanismos y además que las CAUSAS deben preceder sus efectos.
A11: Una vez que se escoge un conjunto candidato, según IIT, los elementos por fuera de ese conjunto son tratados como condiciones de background.
A12: Es decir, no se consideran como variables internas del conjunto sobre el que se hacen las perturbaciones, sino que se fijan sus valores y se tratan como condiciones externas.
A13: Esto significa que esas conexiones por fuera del sistema candidato no son ruidosas sino que se fijan en sus valores actuales.
A15: Estado actual : A B C | C15: 1 0 0
A34: Como todos los mecanismos bajo consideración son condicionalmente independientes, en la práctica el repertorio efecto puede calcularse así:
A39: Esto significa que el repertorio efecto de un solo elemento en el futuro, por ejemplo | N39: es simplemente:
A46: Partimos de la TPM
C48: estado futuro | D48: A | E48: 0 | F48: 1 | G48: 0 | H48: 1 | I48: 0 | J48: 1 | K48: 0 | L48: 1
D49: B | E49: 0 | F49: 0 | G49: 1 | H49: 1 | I49: 0 | J49: 0 | K49: 1 | L49: 1
A50: Estado actual | D50: C | E50: 0 | F50: 0 | G50: 0 | H50: 0 | I50: 1 | J50: 1 | K50: 1 | L50: 1
A51: A | B51: B | C51: C
A52: 0 | B52: 0 | C52: 0 | E52: 1 | F52: 0 | G52: 0 | H52: 0 | I52: 0 | J52: 0 | K52: 0 | L52: 0
A53: 1 | B53: 0 | C53: 0 | E53: 0 | F53: 0 | G53: 0 | H53: 0 | I53: 1 | J53: 0 | K53: 0 | L53: 0
A54: 0 | B54: 1 | C54: 0 | E54: 0 | F54: 0 | G54: 0 | H54: 0 | I54: 0 | J54: 1 | K54: 0 | L54: 0
A55: 1 | B55: 1 | C55: 0 | E55: 0 | F55: 1 | G55: 0 | H55: 0 | I55: 0 | J55: 0 | K55: 0 | L55: 0
A56: 0 | B56: 0 | C56: 1 | E56: 0 | F56: 1 | G56: 0 | H56: 0 | I56: 0 | J56: 0 | K56: 0 | L56: 0
A57: 1 | B57: 0 | C57: 1 | E57: 0 | F57: 0 | G57: 0 | H57: 0 | I57: 0 | J57: 0 | K57: 0 | L57: 1
A58: 0 | B58: 1 | C58: 1 | E58: 0 | F58: 0 | G58: 0 | H58: 0 | I58: 0 | J58: 1 | K58: 0 | L58: 0
A59: 1 | B59: 1 | C59: 1 | E59: 0 | F59: 0 | G59: 0 | H59: 1 | I59: 0 | J59: 0 | K59: 0 | L59: 0
A62: Lo que queremos es calcular | G62: , y según lo mencionado anteriormente, debemos calcular:
A64: 1)
A68: 2) | J68: y
A71: 3)
A76: 1) Vamos a empezar por la primera:
A80: Lo primero que vamos a hacer es marginalizar los elementos del no-purview, es decir, ignorar los elementos por fuera del purview, en este caso B, C, y
A81: marginalizarlos de la TPM y se tratan como si fueran condiciones de background . Empezamos por eliminar B del purview y la TPM quedaría así:
M83: OJO ---------> | N83: luego sumamos pares de columnas cuyos estados solo diferían por
N84: el estado de B y no se normaliza(o sea no dividimos entre 2) yqueda asi:
C85: estado futuro
D86: A | E86: 0 | F86: 1 | G86: 0 | H86: 1 | I86: 0 | J86: 1 | K86: 0 | L86: 1 | P86: E. futuro | Q86: A | R86: 0 | S86: 1 | T86: 0 | U86: 1
A87: Estado actual | D87: C | E87: 0 | F87: 0 | G87: 0 | H87: 0 | I87: 1 | J87: 1 | K87: 1 | L87: 1 | N87: E. Actual | Q87: C | R87: 0 | S87: 0 | T87: 1 | U87: 1
A88: A | B88: B | C88: C | N88: A | O88: B | P88: C
A89: 0 | B89: 0 | C89: 0 | E89: 1 | F89: 0 | G89: 0 | H89: 0 | I89: 0 | J89: 0 | K89: 0 | L89: 0 | N89: 0 | O89: 0 | P89: 0 | R89: =(E89+G89) -> 1 | S89: =(F89+H89) -> 0 | T89: =(I89+K89) -> 0 | U89: =(J89+L89) -> 0
A90: 1 | B90: 0 | C90: 0 | E90: 0 | F90: 0 | G90: 0 | H90: 0 | I90: 1 | J90: 0 | K90: 0 | L90: 0 | N90: 1 | O90: 0 | P90: 0 | R90: =(E90+G90) -> 0 | S90: =(F90+H90) -> 0 | T90: =(I90+K90) -> 1 | U90: =(J90+L90) -> 0
A91: 0 | B91: 1 | C91: 0 | E91: 0 | F91: 0 | G91: 0 | H91: 0 | I91: 0 | J91: 1 | K91: 0 | L91: 0 | N91: 0 | O91: 1 | P91: 0 | R91: =(E91+G91) -> 0 | S91: =(F91+H91) -> 0 | T91: =(I91+K91) -> 0 | U91: =(J91+L91) -> 1
...

Sheet RepEfectoUC
B1: REPERTORIO EFECTO NO RESTRINGIDO (UC unconstrained)
B3: Para calcular la información efecto (ei) también necesitamos calcular la distribución futura o repertorio futuro no restringido
P5: Nota: Cuando por ejemplo, hacemos una partición y una de las partes es (BF|ØC)
D6: Estado Futuro | E6: A | F6: 0 | G6: 1 | H6: 0 | I6: 1 | J6: 0 | K6: 1 | L6: 0 | M6: 1 | P6: calcular P(BF|ØC) es lo mismo que calcular el repertorio NO restringido de B
E7: B | F7: 0 | G7: 0 | H7: 1 | I7: 1 | J7: 0 | K7: 0 | L7: 1 | M7: 1
B8: Estado Actual | E8: C | F8: 0 | G8: 0 | H8: 0 | I8: 0 | J8: 1 | K8: 1 | L8: 1 | M8: 1
B9: A | C9: B | D9: C
B10: 0 | C10: 0 | D10: 0 | F10: 1 | G10: 0 | H10: 0 | I10: 0 | J10: 0 | K10: 0 | L10: 0 | M10: 0
B11: 1 | C11: 0 | D11: 0 | F11: 0 | G11: 0 | H11: 0 | I11: 0 | J11: 1 | K11: 0 | L11: 0 | M11: 0
B12: 0 | C12: 1 | D12: 0 | F12: 0 | G12: 0 | H12: 0 | I12: 0 | J12: 0 | K12: 1 | L12: 0 | M12: 0
B13: 1 | C13: 1 | D13: 0 | F13: 0 | G13: 1 | H13: 0 | I13: 0 | J13: 0 | K13: 0 | L13: 0 | M13: 0
B14: 0 | C14: 0 | D14: 1 | F14: 0 | G14: 1 | H14: 0 | I14: 0 | J14: 0 | K14: 0 | L14: 0 | M14: 0
B15: 1 | C15: 0 | D15: 1 | F15: 0 | G15: 0 | H15: 0 | I15: 0 | J15: 0 | K15: 0 | L15: 0 | M15: 1
B16: 0 | C16: 1 | D16: 1 | F16: 0 | G16: 0 | H16: 0 | I16: 0 | J16: 0 | K16: 1 | L16: 0 | M16: 0
B17: 1 | C17: 1 | D17: 1 | F17: 0 | G17: 0 | H17: 0 | I17: 1 | J17: 0 | K17: 0 | L17: 0 | M17: 0
B19: Sin ninguna restricción de un mecanismo en un estado , el repertorio efecto no restringido | R19: esta dado por:
B23: donde los elementos virtuales son usados para evitar incluir efectos de las correlaciones debido a las entradas comunes.
B24: En la práctica, los cálculos pueden hacerse de forma más sencilla de lo descrito hasta ahora.
B25: • Un truco que podemos usar para simplificar las cosas surge del hecho de que en nuestro modelo de sistemas físicos
B26: descartamos la causalidad instantánea
B27: • Esto se refleja en el requisito de que los elementos sean condicionalmente independientes.
B28: • Es decir, el estado de cada elemento en t+ 1 depende sólo del estado del sistema en t y no de los estados de otros elementos en t+1
B29: • La independencia condicional implica que si p es una distribución sobre los estados de un elemento X y q es la distribución sobre los estados de Y, entonces la distribución conjunta de X e Y es el producto pq
B30: • Entonces, cuando calculamos un repertorio de efectos sobre algún purview, podemos simplemente tomar el producto de los repertorios de efectos individuales de todos los elementos del purview.
B31: • Esto también se aplica a los repertorios de causas, aunque en ese caso los repertorios son sobre los elementos individuales del mecanismo.
B32: • De esta manera, solo necesitamos calcular el repertorio efecto sobre purviews de un solo elemento, asi no podría haber entradas comunes y
B33: en conclusion, no hay necesidad de implementar elementos virtuales
B35: Por tanto para mecanismos independientes condicionalmente, esto seria lo mismo que:
... B43: Aquí se tiene la matriz con todos los posibles estados actuales para mirar la probabilidad de A en el futuro. Mas adelante se hace lo mismo con B y con C
C45: Estado presente | F45: Estado Futuro
C46: A | D46: B | E46: C | F46: P(A=1)
C47: 0 | D47: 0 | E47: 0 | F47: =Ej1RepEfectSinEV!P105 -> 0 | I47: B | J47: C | K47: P(A=1)
C48: 1 | D48: 0 | E48: 0 | F48: =Ej1RepEfectSinEV!P106 -> 0 | I48: 0 | J48: 0 | K48: 0 | M48: P(A=0) | N48: P(A=1)
C49: 0 | D49: 1 | E49: 0 | F49: =Ej1RepEfectSinEV!P107 -> 1 | I49: 1 | J49: 0 | K49: 1 | M49: =1/4 -> 0.25 | N49: =SUM(F47:F54)/8 -> 0.75
C50: 1 | D50: 1 | E50: 0 | F50: =Ej1RepEfectSinEV!P108 -> 1 | I50: 0 | J50: 1 | K50: 1
C51: 0 | D51: 0 | E51: 1 | F51: =Ej1RepEfectSinEV!P109 -> 1 | I51: 1 | J51: 1 | K51: 1
C52: 1 | D52: 0 | E52: 1 | F52: =Ej1RepEfectSinEV!P110 -> 1 | I52: Esto no es necesrio
C53: 0 | D53: 1 | E53: 1 | F53: =Ej1RepEfectSinEV!P111 -> 1
C54: 1 | D54: 1 | E54: 1 | F54: =Ej1RepEfectSinEV!P112 -> 1
C56: Estado presente | F56: Estado Futuro
...

Sheet Ej2RepEfectoSinEV
L3: estado futuro | M3: A | N3: 0 | O3: 1 | P3: 0 | Q3: 1 | R3: 0 | S3: 1 | T3: 0 | U3: 1
M4: B | N4: 0 | O4: 0 | P4: 1 | Q4: 1 | R4: 0 | S4: 0 | T4: 1 | U4: 1
J5: Estado actual | M5: C | N5: 0 | O5: 0 | P5: 0 | Q5: 0 | R5: 1 | S5: 1 | T5: 1 | U5: 1
J6: A | K6: B | L6: C
J7: 0 | K7: 0 | L7: 0 | N7: 1 | O7: 0 | P7: 0 | Q7: 0 | R7: 0 | S7: 0 | T7: 0 | U7: 0
J8: 1 | K8: 0 | L8: 0 | N8: 0 | O8: 0 | P8: 0 | Q8: 0 | R8: 1 | S8: 0 | T8: 0 | U8: 0
J9: 0 | K9: 1 | L9: 0 | N9: 0 | O9: 0 | P9: 0 | Q9: 0 | R9: 0 | S9: 1 | T9: 0 | U9: 0
J10: 1 | K10: 1 | L10: 0 | N10: 0 | O10: 1 | P10: 0 | Q10: 0 | R10: 0 | S10: 0 | T10: 0 | U10: 0
J11: 0 | K11: 0 | L11: 1 | N11: 0 | O11: 1 | P11: 0 | Q11: 0 | R11: 0 | S11: 0 | T11: 0 | U11: 0
J12: 1 | K12: 0 | L12: 1 | N12: 0 | O12: 0 | P12: 0 | Q12: 0 | R12: 0 | S12: 0 | T12: 0 | U12: 1
J13: 0 | K13: 1 | L13: 1 | N13: 0 | O13: 0 | P13: 0 | Q13: 0 | R13: 0 | S13: 1 | T13: 0 | U13: 0
J14: 1 | K14: 1 | L14: 1 | N14: 0 | O14: 0 | P14: 0 | Q14: 1 | R14: 0 | S14: 0 | T14: 0 | U14: 0
A25: Vamos a hacer el cálculo del repertorio efecto para este ejemplo.
A26: Empezaremos haciendo el cálculo sin usar elementos virtuales y tomaremos como referencia la siguiente formula
A31: lo que significa que dado el estado de un sistema en el tiempo t-1, la probabilidad de A, By C se puede calcular independientemente. Esto porque se supone que no hay interaccion instantanea entre
A32: los mecanismos y además que las CAUSAS deben preceder sus efectos.
A33: En nuestro ejemplo trabajaremos el mecanismo C sobre el purview B,C; con lo que nuestra formula seria asi:
A39: Esto require calcular:
A41: 1) | G41: y
A43: 2)
A46: Empezamos calculando 1)
A47: En este paso marginalizamos sobre el purview B (marginalizando los elementos que no hacen parte del purview o sea AyC)
C48: estado futuro | D48: Marginalizamos sobre A (purview) | Y48: Marginalzamos sobre C
D49: B | E49: 0 | F49: 0 | G49: 1 | H49: 1 | I49: 0 | J49: 0 | K49: 1 | L49: 1 | R49: E. futuro | S49: B | T49: 0 | U49: 1 | V49: 0 | W49: 1 | AA49: E. futuro
A50: Estado actual | D50: C | E50: 0 | F50: 0 | G50: 0 | H50: 0 | I50: 1 | J50: 1 | K50: 1 | L50: 1 | P50: E. Actual | S50: C | T50: 0 | U50: 0 | V50: 1 | W50: 1 | Y50: E. Actual | AB50: B | AC50: 0 | AD50: 1
A51: A | B51: B | C51: C | P51: A | Q51: B | R51: C | Y51: A | Z51: B | AA51: C
A52: 0 | B52: 0 | C52: 0 | E52: 1 | F52: 0 | G52: 0 | H52: 0 | I52: 0 | J52: 0 | K52: 0 | L52: 0 | P52: 0 | Q52: 0 | R52: 0 | T52: =(E52+F52) -> 1 | U52: =(G52+H52) -> 0 | V52: =(I52+J52) -> 0 | W52: =(K52+L52) -> 0 | Y52: 0 | Z52: 0 | AA52: 0 | AC52: =(T52+V52) -> 1 | AD52: =(U52+W52) -> 0
A53: 1 | B53: 0 | C53: 0 | E53: 0 | F53: 0 | G53: 0 | H53: 0 | I53: 1 | J53: 0 | K53: 0 | L53: 0 | P53: 1 | Q53: 0 | R53: 0 | T53: =(E53+F53) -> 0 | U53: =(G53+H53) -> 0 | V53: =(I53+J53) -> 1 | W53: =(K53+L53) -> 0 | Y53: 1 | Z53: 0 | AA53: 0 | AC53: =(T53+V53) -> 1 | AD53: =(U53+W53) -> 0
A54: 0 | B54: 1 | C54: 0 | E54: 0 | F54: 0 | G54: 0 | H54: 0 | I54: 0 | J54: 1 | K54: 0 | L54: 0 | P54: 0 | Q54: 1 | R54: 0 | T54: =(E54+F54) -> 0 | U54: =(G54+H54) -> 0 | V54: =(I54+J54) -> 1 | W54: =(K54+L54) -> 0 | Y54: 0 | Z54: 1 | AA54: 0 | AC54: =(T54+V54) -> 1 | AD54: =(U54+W54) -> 0
A55: 1 | B55: 1 | C55: 0 | E55: 0 | F55: 1 | G55: 0 | H55: 0 | I55: 0 | J55: 0 | K55: 0 | L55: 0 | P55: 1 | Q55: 1 | R55: 0 | T55: =(E55+F55) -> 1 | U55: =(G55+H55) -> 0 | V55: =(I55+J55) -> 0 | W55: =(K55+L55) -> 0 | Y55: 1 | Z55: 1 | AA55: 0 | AC55: =(T55+V55) -> 1 | AD55: =(U55+W55) -> 0
A56: 0 | B56: 0 | C56: 1 | E56: 0 | F56: 1 | G56: 0 | H56: 0 | I56: 0 | J56: 0 | K56: 0 | L56: 0 | P56: 0 | Q56: 0 | R56: 1 | T56: =(E56+F56) -> 1 | U56: =(G56+H56) -> 0 | V56: =(I56+J56) -> 0 | W56: =(K56+L56) -> 0 | Y56: 0 | Z56: 0 | AA56: 1 | AC56: =(T56+V56) -> 1 | AD56: =(U56+W56) -> 0
A57: 1 | B57: 0 | C57: 1 | E57: 0 | F57: 0 | G57: 0 | H57: 0 | I57: 0 | J57: 0 | K57: 0 | L57: 1 | P57: 1 | Q57: 0 | R57: 1 | T57: =(E57+F57) -> 0 | U57: =(G57+H57) -> 0 | V57: =(I57+J57) -> 0 | W57: =(K57+L57) -> 1 | Y57: 1 | Z57: 0 | AA57: 1 | AC57: =(T57+V57) -> 0 | AD57: =(U57+W57) -> 1
A58: 0 | B58: 1 | C58: 1 | E58: 0 | F58: 0 | G58: 0 | H58: 0 | I58: 0 | J58: 1 | K58: 0 | L58: 0 | P58: 0 | Q58: 1 | R58: 1 | T58: =(E58+F58) -> 0 | U58: =(G58+H58) -> 0 | V58: =(I58+J58) -> 1 | W58: =(K58+L58) -> 0 | Y58: 0 | Z58: 1 | AA58: 1 | AC58: =(T58+V58) -> 1 | AD58: =(U58+W58) -> 0
A59: 1 | B59: 1 | C59: 1 | E59: 0 | F59: 0 | G59: 0 | H59: 1 | I59: 0 | J59: 0 | K59: 0 | L59: 0 | P59: 1 | Q59: 1 | R59: 1 | T59: =(E59+F59) -> 0 | U59: =(G59+H59) -> 1 | V59: =(I59+J59) -> 0 | W59: =(K59+L59) -> 0 | Y59: 1 | Z59: 1 | AA59: 1 | AC59: =(T59+V59) -> 0 | AD59: =(U59+W59) -> 1
A61: Aquí empezamos a marginalizar sobre el mecanismo C (quitando los elementos que no hacen parte del mecanismo o sea Ay B
A62: Marginalizamos sobre A: | P62: Marginalizamos sobre B
B64: E. futuro | H64: E. futuro | P64: E. futuro | X64: E. futuro
A65: Estado actual | C65: B | D65: 0 | E65: 1 | G65: E. actual | I65: B | J65: 0 | K65: 1 | Q65: B | R65: 0 | S65: 1 | Y65: B | Z65: 0 | AA65: 1
A66: B | B66: C | G66: B | H66: C | O66: E. actual | P66: C | W66: E. actual | X66: C
A67: 0 | B67: 0 | D67: =AC52 -> 1 | E67: =AD52 -> 0 | G67: 0 | H67: 0 | J67: =(D67+D68)/2 -> 1 | K67: =(E67+E68)/2 -> 0 | P67: 0 | R67: =J67 -> 1 | S67: =K67 -> 0 | X67: 0 | Z67: =(R67+R68)/2 -> 1 | AA67: =(S67+S68)/2 -> 0
...

Sheet EjParticion
A1: Vamos a desarrollar el siguiente ejemplo completo con el fin de hacer las particiones.
A2: Tenemos la TPM base del sistema
D5: estado futuro | E5: A | F5: 0 | G5: 1 | H5: 0 | I5: 1 | J5: 0 | K5: 1 | L5: 0 | M5: 1
E6: B | F6: 0 | G6: 0 | H6: 1 | I6: 1 | J6: 0 | K6: 0 | L6: 1 | M6: 1
B7: Estado actual | E7: C | F7: 0 | G7: 0 | H7: 0 | I7: 0 | J7: 1 | K7: 1 | L7: 1 | M7: 1
B8: A | C8: B | D8: C
B9: 0 | C9: 0 | D9: 0 | F9: 1 | G9: 0 | H9: 0 | I9: 0 | J9: 0 | K9: 0 | L9: 0 | M9: 0
B10: 1 | C10: 0 | D10: 0 | F10: 0 | G10: 0 | H10: 0 | I10: 0 | J10: 1 | K10: 0 | L10: 0 | M10: 0
B11: 0 | C11: 1 | D11: 0 | F11: 0 | G11: 0 | H11: 0 | I11: 0 | J11: 0 | K11: 1 | L11: 0 | M11: 0
B12: 1 | C12: 1 | D12: 0 | F12: 0 | G12: 1 | H12: 0 | I12: 0 | J12: 0 | K12: 0 | L12: 0 | M12: 0
B13: 0 | C13: 0 | D13: 1 | F13: 0 | G13: 1 | H13: 0 | I13: 0 | J13: 0 | K13: 0 | L13: 0 | M13: 0
B14: 1 | C14: 0 | D14: 1 | F14: 0 | G14: 0 | H14: 0 | I14: 0 | J14: 0 | K14: 0 | L14: 0 | M14: 1
B15: 0 | C15: 1 | D15: 1 | F15: 0 | G15: 0 | H15: 0 | I15: 0 | J15: 0 | K15: 1 | L15: 0 | M15: 0
B16: 1 | C16: 1 | D16: 1 | F16: 0 | G16: 0 | H16: 0 | I16: 1 | J16: 0 | K16: 0 | L16: 0 | M16: 0
A19: Este es el mecanismo AC sobre el purview ABC
N25: Este problema podemos representarlo asi:
A39: 1)Hallamos la distribución de probabilidadess para el sistema en el estado inicial A=1 C=0, porque B no hace parte de lo que queremos revisar.
A40: En este orden de ideas, según la fórmula definida previamente calcularemos cada parte y luego aplicaremos el producto tensor. consiguiente
A41: Debemos calcular:
A42: 1)
A44: 2)
A46: 3)
A48: Empezando por 1) se tiene:
A49: Debemos marginalizar sobre el purview en B y C, obteniendo:
S50: Luego se marginaliza sobre el mecanismo
C51: E. futuro | D51: A | E51: 0 | F51: 1 | G51: 0 | H51: 1
A52: E. Actual | D52: C | E52: 0 | F52: 0 | G52: 1 | H52: 1 | O52: A | P52: 0 | Q52: 1
A53: A | B53: B | C53: C | L53: A | M53: B | N53: C | U53: A | V53: 0 | W53: 1 | Z53: Aquí se debe normalizar (se divide por 2)
A54: 0 | B54: 0 | C54: 0 | E54: 1 | F54: 0 | G54: 0 | H54: 0 | L54: 0 | M54: 0 | N54: 0 | P54: =E54+G54 -> 1 | Q54: =F54+H54 -> 0 | S54: A | T54: C
A55: 1 | B55: 0 | C55: 0 | E55: 0 | F55: 0 | G55: 1 | H55: 0 | L55: 1 | M55: 0 | N55: 0 | P55: =E55+G55 -> 1 | Q55: =F55+H55 -> 0 | S55: 0 | T55: 0 | V55: =P54 -> 1 | W55: =Q54 -> 0 | AB55: A | AC55: 0 | AD55: 1
A56: 0 | B56: 1 | C56: 0 | E56: 0 | F56: 0 | G56: 0 | H56: 1 | L56: 0 | M56: 1 | N56: 0 | P56: =E56+G56 -> 0 | Q56: =F56+H56 -> 1 | S56: 1 | T56: 0 | V56: =P55 -> 1 | W56: =Q55 -> 0 | Z56: A | AA56: C
A57: 1 | B57: 1 | C57: 0 | E57: 0 | F57: 1 | G57: 0 | H57: 0 | L57: 1 | M57: 1 | N57: 0 | P57: =E57+G57 -> 0 | Q57: =F57+H57 -> 1 | S57: 0 | T57: 0 | V57: =P56 -> 0 | W57: =Q56 -> 1 | Z57: 0 | AA57: 0 | AC57: =(V55+V57)/2 -> 0.5 | AD57: =(W55+W57)/2 -> 0.5
A58: 0 | B58: 0 | C58: 1 | E58: 0 | F58: 1 | G58: 0 | H58: 0 | L58: 0 | M58: 0 | N58: 1 | P58: =E58+G58 -> 0 | Q58: =F58+H58 -> 1 | S58: 1 | T58: 0 | V58: =P57 -> 0 | W58: =Q57 -> 1 | Z58: 1 | AA58: 0 | AC58: =(V56+V58)/2 -> 0.5 | AD58: =(W56+W58)/2 -> 0.5
A59: 1 | B59: 0 | C59: 1 | E59: 0 | F59: 0 | G59: 0 | H59: 1 | L59: 1 | M59: 0 | N59: 1 | P59: =E59+G59 -> 0 | Q59: =F59+H59 -> 1 | S59: 0 | T59: 1 | V59: =P58 -> 0 | W59: =Q58 -> 1 | Z59: 0 | AA59: 1 | AC59: =(V59+V61)/2 -> 0 | AD59: =(W59+W61)/2 -> 1
A60: 0 | B60: 1 | C60: 1 | E60: 0 | F60: 0 | G60: 0 | H60: 1 | L60: 0 | M60: 1 | N60: 1 | P60: =E60+G60 -> 0 | Q60: =F60+H60 -> 1 | S60: 1 | T60: 1 | V60: =P59 -> 0 | W60: =Q59 -> 1 | Z60: 1 | AA60: 1 | AC60: =(V60+V62)/2 -> 0 | AD60: =(W60+W62)/2 -> 1
A61: 1 | B61: 1 | C61: 1 | E61: 0 | F61: 1 | G61: 0 | H61: 0 | L61: 1 | M61: 1 | N61: 1 | P61: =E61+G61 -> 0 | Q61: =F61+H61 -> 1 | S61: 0 | T61: 1 | V61: =P60 -> 0 | W61: =Q60 -> 1
E62: =SUM(E54:E61)/8 -> 0.125 | F62: =SUM(F54:F61)/8 -> 0.375 | G62: =SUM(G54:G61)/8 -> 0.125 | H62: =SUM(H54:H61)/8 -> 0.375 | P62: =SUM(P54:P61)/8 -> 0.25 | Q62: =SUM(Q54:Q61)/8 -> 0.75 | S62: 1 | T62: 1 | V62: =P61 -> 0 | W62: =Q61 -> 1
A63: Ahora seguimos con 2)
A64: Debemos marginalizar sobre el purview en A y C
A65: luego sumamos pares de columnas cuyos estados solo diferían por | O65: luego sumamos pares de columnas cuyos estados
...

Sheet EjemploVacio
B2: EJEMPLO DE UNA DESCOMPOSICIÓN DE UN SISTEMA
A28: Aquí tenemos la distribución de probabilidades del sistema a analizar:
G30: B | H30: 0 | I30: 1
D31: A | E31: B | F31: C
D32: 0 | E32: 0 | F32: 0 | H32: 1 | I32: 0
D33: 1 | E33: 0 | F33: 0 | H33: 1 | I33: 0
D34: 0 | E34: 1 | F34: 0 | H34: 1 | I34: 0
D35: 1 | E35: 1 | F35: 0 | H35: 1 | I35: 0
D36: 0 | E36: 0 | F36: 1 | H36: 1 | I36: 0
D37: 1 | E37: 0 | F37: 1 | H37: 0 | I37: 1
D38: 0 | E38: 1 | F38: 1 | H38: 1 | I38: 0
D39: 1 | E39: 1 | F39: 1 | H39: 0 | I39: 1
A42: Ahora calcularemos las distribuciones de probailidades de cada componente de la partición propuesta en este ejemplo:
F44: se marginaliza sobre el mecanismo
G45: E. Futuro
F46: E.Presente | H46: B | I46: 0 | J46: 1
F47: B | G47: C | N47: E. futuro
F48: 0 | G48: 0 | I48: 1 | J48: 0 | M48: E. actual | O48: B | P48: 0 | Q48: 1
F49: 0 | G49: 0 | I49: 1 | J49: 0 | M49: B | N49: C
F50: 1 | G50: 0 | I50: 1 | J50: 0 | M50: 0 | N50: 0 | P50: 1 | Q50: 0
F51: 1 | G51: 0 | I51: 1 | J51: 0 | M51: 1 | N51: 0 | P51: 1 | Q51: 0
F52: 0 | G52: 1 | I52: 1 | J52: 0 | M52: 0 | N52: 1 | P52: 0.5 | Q52: 0.5
F53: 0 | G53: 1 | I53: 0 | J53: 1 | M53: 1 | N53: 1 | P53: 0.5 | Q53: 0.5
F54: 1 | G54: 1 | I54: 1 | J54: 0
F55: 1 | G55: 1 | I55: 0 | J55: 1
A58: Ahora calculamos el otro componente:
F60: Primero se hace la marginalización sobre C como se presenta a continuación: | S60: Luego se hace la marginalización sobre B, como se presenta a | AH60: Asi queda luego de las marginalizaciones:
H61: A | I61: 0 | J61: 1 | K61: 0 | L61: 1 | M61: 0 | N61: 1 | O61: 0 | P61: 1 | S61: continuacion: | V61: A | W61: 0 | X61: 1 | Y61: 0 | Z61: 1 | AA61: 0 | AB61: 1 | AC61: 0 | AD61: 1 | AJ61: A | AK61: 0 | AL61: 1 | AM61: 0 | AN61: 1 | AO61: 0 | AP61: 1 | AQ61: 0 | AR61: 1
H62: B | I62: 0 | J62: 0 | K62: 1 | L62: 1 | M62: 0 | N62: 0 | O62: 1 | P62: 1 | V62: B | W62: 0 | X62: 0 | Y62: 1 | Z62: 1 | AA62: 0 | AB62: 0 | AC62: 1 | AD62: 1 | AJ62: B | AK62: 0 | AL62: 0 | AM62: 1 | AN62: 1 | AO62: 0 | AP62: 0 | AQ62: 1 | AR62: 1
F63: E. presente | G63: E. futuro | H63: C | I63: 0 | J63: 0 | K63: 0 | L63: 0 | M63: 1 | N63: 1 | O63: 1 | P63: 1 | U63: E. futuro | V63: C | W63: 0 | X63: 0 | Y63: 0 | Z63: 0 | AA63: 1 | AB63: 1 | AC63: 1 | AD63: 1 | AI63: E.futuro | AJ63: C | AK63: 0 | AL63: 0 | AM63: 0 | AN63: 0 | AO63: 1 | AP63: 1 | AQ63: 1 | AR63: 1 | AV63: A
F64: A | G64: B | T64: A | AH64: A
F65: 0 | G65: 0 | I65: 1 | J65: 0 | K65: 0 | L65: 0 | M65: 0 | N65: 0 | O65: 0 | P65: 0 | T65: 0 | W65: =(I65+I69)/2 -> 0.5 | X65: =(J65+J69)/2 -> 0.5 | Y65: =(K65+K69)/2 -> 0 | Z65: =(L65+L69)/2 -> 0 | AA65: =(M65+M69)/2 -> 0 | AB65: =(N65+N69)/2 -> 0 | AC65: =(O65+O69)/2 -> 0 | AD65: =(P65+P69)/2 -> 0 | AH65: 0 | AK65: =(W65+W67)/2 -> 0.25 | AL65: =(X65+X67)/2 -> 0.25 | AM65: =(Y65+Y67)/2 -> 0 | AN65: =(Z65+Z67)/2 -> 0 | AO65: =(AA65+AA67)/2 -> 0 | AP65: =(AB65+AB67)/2 -> 0.5 | AQ65: =(AC65+AC67)/2 -> 0 | AR65: =(AD65+AD67)/2 -> 0 | AS65: =SUM(AK65:AR65) -> 1 | AV65: 1 | AW65: =$AS$66 -> 1
F66: 1 | G66: 0 | I66: 0 | J66: 0 | K66: 0 | L66: 0 | M66: 1 | N66: 0 | O66: 0 | P66: 0 | T66: 1 | W66: =(I66+I70)/2 -> 0 | X66: =(J66+J70)/2 -> 0 | Y66: =(K66+K70)/2 -> 0 | Z66: =(L66+L70)/2 -> 0 | AA66: =(M66+M70)/2 -> 0.5 | AB66: =(N66+N70)/2 -> 0 | AC66: =(O66+O70)/2 -> 0 | AD66: =(P66+P70)/2 -> 0.5 | AH66: 1 | AK66: =(W66+W68)/2 -> 0 | AL66: =(X66+X68)/2 -> 0.25 | AM66: =(Y66+Y68)/2 -> 0 | AN66: =(Z66+Z68)/2 -> 0.25 | AO66: =(AA66+AA68)/2 -> 0.25 | AP66: =(AB66+AB68)/2 -> 0 | AQ66: =(AC66+AC68)/2 -> 0 | AR66: =(AD66+AD68)/2 -> 0.25 | AS66: =SUM(AK66:AR66) -> 1
F67: 0 | G67: 1 | I67: 0 | J67: 0 | K67: 0 | L67: 0 | M67: 0 | N67: 1 | O67: 0 | P67: 0 | T67: 0 | W67: =(I67+I71)/2 -> 0 | X67: =(J67+J71)/2 -> 0 | Y67: =(K67+K71)/2 -> 0 | Z67: =(L67+L71)/2 -> 0 | AA67: =(M67+M71)/2 -> 0 | AB67: =(N67+N71)/2 -> 1 | AC67: =(O67+O71)/2 -> 0 | AD67: =(P67+P71)/2 -> 0
F68: 1 | G68: 1 | I68: 0 | J68: 1 | K68: 0 | L68: 0 | M68: 0 | N68: 0 | O68: 0 | P68: 0 | T68: 1 | W68: =(I68+I72)/2 -> 0 | X68: =(J68+J72)/2 -> 0.5 | Y68: =(K68+K72)/2 -> 0 | Z68: =(L68+L72)/2 -> 0.5 | AA68: =(M68+M72)/2 -> 0 | AB68: =(N68+N72)/2 -> 0 | AC68: =(O68+O72)/2 -> 0 | AD68: =(P68+P72)/2 -> 0
F69: 0 | G69: 0 | I69: 0 | J69: 1 | K69: 0 | L69: 0 | M69: 0 | N69: 0 | O69: 0 | P69: 0
F70: 1 | G70: 0 | I70: 0 | J70: 0 | K70: 0 | L70: 0 | M70: 0 | N70: 0 | O70: 0 | P70: 1
F71: 0 | G71: 1 | I71: 0 | J71: 0 | K71: 0 | L71: 0 | M71: 0 | N71: 1 | O71: 0 | P71: 0
F72: 1 | G72: 1 | I72: 0 | J72: 0 | K72: 0 | L72: 1 | M72: 0 | N72: 0 | O72: 0 | P72: 0
A77: Ahora hacemos el producto tensor de las dos particiones
...

Sheet II
P19: estado futuro | Q19: A | R19: 0 | S19: 1 | T19: 0 | U19: 1 | V19: 0 | W19: 1 | X19: 0 | Y19: 1
Q20: B | R20: 0 | S20: 0 | T20: 1 | U20: 1 | V20: 0 | W20: 0 | X20: 1 | Y20: 1
N21: Estado actual | Q21: C | R21: 0 | S21: 0 | T21: 0 | U21: 0 | V21: 1 | W21: 1 | X21: 1 | Y21: 1
N22: A | O22: B | P22: C
N23: 0 | O23: 0 | P23: 0 | R23: 1 | S23: 0 | T23: 0 | U23: 0 | V23: 0 | W23: 0 | X23: 0 | Y23: 0
N24: 1 | O24: 0 | P24: 0 | R24: 0 | S24: 0 | T24: 0 | U24: 0 | V24: 1 | W24: 0 | X24: 0 | Y24: 0
N25: 0 | O25: 1 | P25: 0 | R25: 0 | S25: 0 | T25: 0 | U25: 0 | V25: 0 | W25: 1 | X25: 0 | Y25: 0
N26: 1 | O26: 1 | P26: 0 | R26: 0 | S26: 1 | T26: 0 | U26: 0 | V26: 0 | W26: 0 | X26: 0 | Y26: 0
N27: 0 | O27: 0 | P27: 1 | R27: 0 | S27: 1 | T27: 0 | U27: 0 | V27: 0 | W27: 0 | X27: 0 | Y27: 0
N28: 1 | O28: 0 | P28: 1 | R28: 0 | S28: 0 | T28: 0 | U28: 0 | V28: 0 | W28: 0 | X28: 0 | Y28: 1
N29: 0 | O29: 1 | P29: 1 | R29: 0 | S29: 0 | T29: 0 | U29: 0 | V29: 0 | W29: 1 | X29: 0 | Y29: 0
N30: 1 | O30: 1 | P30: 1 | R30: 0 | S30: 0 | T30: 0 | U30: 1 | V30: 0 | W30: 0 | X30: 0 | Y30: 0
A31: Vamos a calcular la diatribución de probabilidades para el sistema completo
G35: Partimos de:
K37: B | L37: 0 | M37: 1
H38: A | I38: B | J38: C
H39: 0 | I39: 0 | J39: 0 | L39: 1 | M39: 0
H40: 1 | I40: 0 | J40: 0 | L40: 1 | M40: 0 | Q40: B | R40: 0 | S40: 1
H41: 0 | I41: 1 | J41: 0 | L41: 1 | M41: 0 | O41: A | P41: B | V41: B | W41: 0 | X41: 1
H42: 1 | I42: 1 | J42: 0 | L42: 1 | M42: 0 | O42: 0 | P42: 0 | R42: =(L39+L43)/2 -> 1 | S42: =(M39+M43)/2 -> 0 | U42: A
H43: 0 | I43: 0 | J43: 1 | L43: 1 | M43: 0 | O43: 1 | P43: 0 | R43: =(L40+L44)/2 -> 0.5 | S43: =(M40+M44)/2 -> 0.5 | U43: 0 | W43: =(R42+R44)/2 -> 1 | X43: =(S42+S44)/2 -> 0
H44: 1 | I44: 0 | J44: 1 | L44: 0 | M44: 1 | O44: 0 | P44: 1 | R44: =(L41+L45)/2 -> 1 | S44: =(M41+M45)/2 -> 0 | U44: 1 | W44: =(R43+R45)/2 -> 0.5 | X44: =(S43+S45)/2 -> 0.5
H45: 0 | I45: 1 | J45: 1 | L45: 1 | M45: 0 | O45: 1 | P45: 1 | R45: =(L42+L46)/2 -> 0.5 | S45: =(M42+M46)/2 -> 0.5
H46: 1 | I46: 1 | J46: 1 | L46: 0 | M46: 1
C48: Si queremos expandir el REPERTORIO EFECTO al espacio de estados completo para eso multiplicamos por la distribucion no restringida sobre los estados proximos de A y C
C49: así:
T50: A | U50: 0 | V50: 1 | W50: 0 | X50: 1 | Y50: 0 | Z50: 1 | AA50: 0 | AB50: 1
C51: A | D51: 0 | E51: 1 | I51: B | J51: 0 | K51: 1 | N51: C | O51: 0 | P51: 1 | T51: B | U51: 0 | V51: 0 | W51: 1 | X51: 1 | Y51: 0 | Z51: 0 | AA51: 1 | AB51: 1
D52: =RepEfectoUC!M49 -> 0.25 | E52: =RepEfectoUC!N49 -> 0.75 | H52: A | O52: =RepEfectoUC!M72 -> 0.5 | P52: =RepEfectoUC!N72 -> 0.5 | T52: C | U52: 0 | V52: 0 | W52: 0 | X52: 0 | Y52: 1 | Z52: 1 | AA52: 1 | AB52: 1
H53: 1 | J53: =W44 -> 0.5 | K53: =X44 -> 0.5 | S53: A | U53: =D52*J53*O52 -> 0.0625 | V53: =E52*J53*O52 -> 0.1875 | W53: =D52*K53*O52 -> 0.0625 | X53: =E52*K53*O52 -> 0.1875 | Y53: =D52*J53*P52 -> 0.0625 | Z53: =E52*J53*P52 -> 0.1875 | AA53: =D52*K53*P52 -> 0.0625 | AB53: =E52*K53*P52 -> 0.1875
A65: Luego se calculara para la única partición posible para este subsistema cual es su distribución de probabilidades y luego se compara con la distribucion inicial del sistema sin partir
A71: entonces debemos calcular lo siguiente:
B72: P(ØF|AC) | E72: P(BF|ØC)
A74: 1) Empezamos calculando P(ØF|AC), para esto marginalizamos en el estado t sobre B y C, asi:
C76: A | D76: 0 | E76: 1 | F76: 0 | G76: 1 | H76: 0 | I76: 1 | J76: 0 | K76: 1 | P76: A | Q76: 0 | R76: 1 | S76: 0 | T76: 1 | U76: 0 | V76: 1 | W76: 0 | X76: 1
C77: B | D77: 0 | E77: 0 | F77: 1 | G77: 1 | H77: 0 | I77: 0 | J77: 1 | K77: 1 | P77: B | Q77: 0 | R77: 0 | S77: 1 | T77: 1 | U77: 0 | V77: 0 | W77: 1 | X77: 1
B78: E. futuro | C78: C | D78: 0 | E78: 0 | F78: 0 | G78: 0 | H78: 1 | I78: 1 | J78: 1 | K78: 1 | O78: E. futuro | P78: C | Q78: 0 | R78: 0 | S78: 0 | T78: 0 | U78: 1 | V78: 1 | W78: 1 | X78: 1
A79: A | N79: A | AB79: A
A80: 0 | D80: 0.5 | E80: 0.5 | F80: 0 | G80: 0 | H80: 0 | I80: 0 | J80: 0 | K80: 0 | N80: 0 | Q80: =(D80+D82)/2 -> 0.25 | R80: =(E80+E82)/2 -> 0.25 | S80: =(F80+F82)/2 -> 0 | T80: =(G80+G82)/2 -> 0 | U80: =(H80+H82)/2 -> 0 | V80: =(I80+I82)/2 -> 0.5 | W80: =(J80+J82)/2 -> 0 | X80: =(K80+K82)/2 -> 0
A81: 1 | D81: 0 | E81: 0 | F81: 0 | G81: 0 | H81: 0.5 | I81: 0 | J81: 0 | K81: 0.5 | N81: 1 | Q81: =(D81+D83)/2 -> 0 | R81: =(E81+E83)/2 -> 0.25 | S81: =(F81+F83)/2 -> 0 | T81: =(G81+G83)/2 -> 0.25 | U81: =(H81+H83)/2 -> 0.25 | V81: =(I81+I83)/2 -> 0 | W81: =(J81+J83)/2 -> 0 | X81: =(K81+K83)/2 -> 0.25 | AB81: 1 | AC81: =SUM(Q81:X81) -> 1
...

Sheet EMD
B2: Sea X1 y X2 dos variables aleatorias con su correspondiente espacio de estados (Por ej. X1=B y X2=C). Si X1 y X2 son independientes y
B3: sean p1 y q1 dos distribuciones de probabilidades en X1 y sean p2 y q2 dos distribuciones de probabilidades en X2 | S3: Dado que los nodos son independientes, la EMD entre los repertorios efecto es igual a la suma de las EMD entre las distribuciones marginales de cada nodo,
S4: y la EMD entre las distribuciones marginales de un nodo es la diferencia absoluta en las probabilidades de que el nodo esté APAGADO.
D5: B | E5: 0 | F5: 1 | G5: 0 | H5: 1
D6: C | E6: 0 | F6: 0 | G6: 1 | H6: 1
C8: p | E8: 0.5 | F8: 0 | G8: 0.5 | H8: 0 | P8: 0.5 | Q8: 0.5
C10: Sea
C11: p1= (En B)
C12: p2= (En C)
D16: B | E16: 0 | F16: 1 | G16: 0 | H16: 1
D17: C | E17: 0 | F17: 0 | G17: 1 | H17: 1
C18: q | E18: 0.25 | F18: 0.25 | G18: 0.25 | H18: 0.25
L19: 0.5 | M19: 0.5 | P19: 0.5 | Q19: 0.5
C20: Sea
C21: q1= (En B)
C22: q2= (En C)
E24: EMD(p,q) = EMD(p1,q1) + EMD(p2,q2)
